I'm sorry, but an uncaught exception occurred.

While running game code:
  File "game/argue.rpy", line 13, in script
    quesion1 "Anyone can make mistake you know."
Exception: Sayer 'quesion1' is not defined.

-- Full Traceback ------------------------------------------------------------

Full traceback:
  File "game/argue.rpy", line 13, in script
    quesion1 "Anyone can make mistake you know."
  File "D:\MY DATA\ren'py\renpy-7.1.3-sdk\renpy\ast.py", line 650, in execute
    who = eval_who(self.who, self.who_fast)
  File "D:\MY DATA\ren'py\renpy-7.1.3-sdk\renpy\ast.py", line 560, in eval_who
    raise Exception("Sayer '%s' is not defined." % who.encode("utf-8"))
Exception: Sayer 'quesion1' is not defined.

Windows-8-6.2.9200
Ren'Py 7.1.3.1092
Blury 1.0
Tue Dec 25 21:39:10 2018
